[2024-05-16T18:45:03.400+0000] {local_task_job_runner.py:120} INFO - ::group::Pre task execution logs
[2024-05-16T18:45:03.418+0000] {taskinstance.py:2076} INFO - Dependencies all met for dep_context=non-requeueable deps ti=<TaskInstance: fetch_and_store_data.store_data scheduled__2024-05-16T18:42:00+00:00 [queued]>
[2024-05-16T18:45:03.428+0000] {taskinstance.py:2076} INFO - Dependencies all met for dep_context=requeueable deps ti=<TaskInstance: fetch_and_store_data.store_data scheduled__2024-05-16T18:42:00+00:00 [queued]>
[2024-05-16T18:45:03.429+0000] {taskinstance.py:2306} INFO - Starting attempt 1 of 2
[2024-05-16T18:45:03.437+0000] {taskinstance.py:2330} INFO - Executing <Task(PythonOperator): store_data> on 2024-05-16 18:42:00+00:00
[2024-05-16T18:45:03.444+0000] {warnings.py:110} WARNING - /home/***/.local/lib/python3.12/site-packages/***/task/task_runner/standard_task_runner.py:61: DeprecationWarning: This process (pid=459) is multi-threaded, use of fork() may lead to deadlocks in the child.
  pid = os.fork()

[2024-05-16T18:45:03.445+0000] {standard_task_runner.py:63} INFO - Started process 461 to run task
[2024-05-16T18:45:03.445+0000] {standard_task_runner.py:90} INFO - Running: ['***', 'tasks', 'run', 'fetch_and_store_data', 'store_data', 'scheduled__2024-05-16T18:42:00+00:00', '--job-id', '31', '--raw', '--subdir', 'DAGS_FOLDER/fetch_and_store_data.py', '--cfg-path', '/tmp/tmp8ocmxcao']
[2024-05-16T18:45:03.446+0000] {standard_task_runner.py:91} INFO - Job 31: Subtask store_data
[2024-05-16T18:45:03.468+0000] {task_command.py:426} INFO - Running <TaskInstance: fetch_and_store_data.store_data scheduled__2024-05-16T18:42:00+00:00 [running]> on host 523a7de3ce3b
[2024-05-16T18:45:03.504+0000] {taskinstance.py:2648} INFO - Exporting env vars: AIRFLOW_CTX_DAG_OWNER='***' AIRFLOW_CTX_DAG_ID='fetch_and_store_data' AIRFLOW_CTX_TASK_ID='store_data' AIRFLOW_CTX_EXECUTION_DATE='2024-05-16T18:42:00+00:00' AIRFLOW_CTX_TRY_NUMBER='1' AIRFLOW_CTX_DAG_RUN_ID='scheduled__2024-05-16T18:42:00+00:00'
[2024-05-16T18:45:03.506+0000] {taskinstance.py:430} INFO - ::endgroup::
[2024-05-16T18:45:03.514+0000] {base.py:84} INFO - Using connection ID 'fraud_detection_pg' for task execution.
[2024-05-16T18:45:03.519+0000] {taskinstance.py:441} INFO - ::group::Post task execution logs
[2024-05-16T18:45:03.520+0000] {taskinstance.py:2905} ERROR - Task failed with exception
Traceback (most recent call last):
  File "/home/airflow/.local/lib/python3.12/site-packages/airflow/models/taskinstance.py", line 465, in _execute_task
    result = _execute_callable(context=context, **execute_callable_kwargs)
             ^^^^^^^^^^^^^^^^^^^^^^^^^^^^^^^^^^^^^^^^^^^^^^^^^^^^^^^^^^^^^
  File "/home/airflow/.local/lib/python3.12/site-packages/airflow/models/taskinstance.py", line 432, in _execute_callable
    return execute_callable(context=context, **execute_callable_kwargs)
           ^^^^^^^^^^^^^^^^^^^^^^^^^^^^^^^^^^^^^^^^^^^^^^^^^^^^^^^^^^^^
  File "/home/airflow/.local/lib/python3.12/site-packages/airflow/models/baseoperator.py", line 400, in wrapper
    return func(self, *args, **kwargs)
           ^^^^^^^^^^^^^^^^^^^^^^^^^^^
  File "/home/airflow/.local/lib/python3.12/site-packages/airflow/operators/python.py", line 235, in execute
    return_value = self.execute_callable()
                   ^^^^^^^^^^^^^^^^^^^^^^^
  File "/home/airflow/.local/lib/python3.12/site-packages/airflow/operators/python.py", line 252, in execute_callable
    return self.python_callable(*self.op_args, **self.op_kwargs)
           ^^^^^^^^^^^^^^^^^^^^^^^^^^^^^^^^^^^^^^^^^^^^^^^^^^^^^
  File "/opt/airflow/dags/fetch_and_store_data.py", line 83, in store_data
    connection = pg_hook.get_conn()
                 ^^^^^^^^^^^^^^^^^^
  File "/home/airflow/.local/lib/python3.12/site-packages/airflow/providers/postgres/hooks/postgres.py", line 161, in get_conn
    self.conn = psycopg2.connect(**conn_args)
                ^^^^^^^^^^^^^^^^^^^^^^^^^^^^^
  File "/home/airflow/.local/lib/python3.12/site-packages/psycopg2/__init__.py", line 122, in connect
    conn = _connect(dsn, connection_factory=connection_factory, **kwasync)
           ^^^^^^^^^^^^^^^^^^^^^^^^^^^^^^^^^^^^^^^^^^^^^^^^^^^^^^^^^^^^^^^
psycopg2.OperationalError: connection to server at "postgres" (172.18.0.3), port 5432 failed: FATAL:  password authentication failed for user "postgres"

[2024-05-16T18:45:03.527+0000] {taskinstance.py:1206} INFO - Marking task as UP_FOR_RETRY. dag_id=fetch_and_store_data, task_id=store_data, run_id=scheduled__2024-05-16T18:42:00+00:00, execution_date=20240516T184200, start_date=20240516T184503, end_date=20240516T184503
[2024-05-16T18:45:03.533+0000] {standard_task_runner.py:110} ERROR - Failed to execute job 31 for task store_data (connection to server at "postgres" (172.18.0.3), port 5432 failed: FATAL:  password authentication failed for user "postgres"
; 461)
[2024-05-16T18:45:03.547+0000] {local_task_job_runner.py:240} INFO - Task exited with return code 1
[2024-05-16T18:45:03.565+0000] {taskinstance.py:3498} INFO - 0 downstream tasks scheduled from follow-on schedule check
[2024-05-16T18:45:03.566+0000] {local_task_job_runner.py:222} INFO - ::endgroup::
