[2024-05-17T05:33:04.924+0000] {local_task_job_runner.py:120} INFO - ::group::Pre task execution logs
[2024-05-17T05:33:04.941+0000] {taskinstance.py:2076} INFO - Dependencies all met for dep_context=non-requeueable deps ti=<TaskInstance: fetch_and_store_data.store_data scheduled__2024-05-17T05:30:00+00:00 [queued]>
[2024-05-17T05:33:04.948+0000] {taskinstance.py:2076} INFO - Dependencies all met for dep_context=requeueable deps ti=<TaskInstance: fetch_and_store_data.store_data scheduled__2024-05-17T05:30:00+00:00 [queued]>
[2024-05-17T05:33:04.949+0000] {taskinstance.py:2306} INFO - Starting attempt 1 of 2
[2024-05-17T05:33:04.962+0000] {taskinstance.py:2330} INFO - Executing <Task(PythonOperator): store_data> on 2024-05-17 05:30:00+00:00
[2024-05-17T05:33:04.971+0000] {warnings.py:110} WARNING - /home/***/.local/lib/python3.12/site-packages/***/task/task_runner/standard_task_runner.py:61: DeprecationWarning: This process (pid=257) is multi-threaded, use of fork() may lead to deadlocks in the child.
  pid = os.fork()

[2024-05-17T05:33:04.972+0000] {standard_task_runner.py:63} INFO - Started process 259 to run task
[2024-05-17T05:33:04.974+0000] {standard_task_runner.py:90} INFO - Running: ['***', 'tasks', 'run', 'fetch_and_store_data', 'store_data', 'scheduled__2024-05-17T05:30:00+00:00', '--job-id', '74', '--raw', '--subdir', 'DAGS_FOLDER/fetch_and_store_data.py', '--cfg-path', '/tmp/tmp0zywl6yh']
[2024-05-17T05:33:04.976+0000] {standard_task_runner.py:91} INFO - Job 74: Subtask store_data
[2024-05-17T05:33:05.019+0000] {task_command.py:426} INFO - Running <TaskInstance: fetch_and_store_data.store_data scheduled__2024-05-17T05:30:00+00:00 [running]> on host a9c7835cc043
[2024-05-17T05:33:05.086+0000] {taskinstance.py:2648} INFO - Exporting env vars: AIRFLOW_CTX_DAG_OWNER='***' AIRFLOW_CTX_DAG_ID='fetch_and_store_data' AIRFLOW_CTX_TASK_ID='store_data' AIRFLOW_CTX_EXECUTION_DATE='2024-05-17T05:30:00+00:00' AIRFLOW_CTX_TRY_NUMBER='1' AIRFLOW_CTX_DAG_RUN_ID='scheduled__2024-05-17T05:30:00+00:00'
[2024-05-17T05:33:05.088+0000] {taskinstance.py:430} INFO - ::endgroup::
[2024-05-17T05:33:05.100+0000] {taskinstance.py:441} INFO - ::group::Post task execution logs
[2024-05-17T05:33:05.102+0000] {taskinstance.py:2905} ERROR - Task failed with exception
Traceback (most recent call last):
  File "/home/airflow/.local/lib/python3.12/site-packages/airflow/models/taskinstance.py", line 465, in _execute_task
    result = _execute_callable(context=context, **execute_callable_kwargs)
             ^^^^^^^^^^^^^^^^^^^^^^^^^^^^^^^^^^^^^^^^^^^^^^^^^^^^^^^^^^^^^
  File "/home/airflow/.local/lib/python3.12/site-packages/airflow/models/taskinstance.py", line 432, in _execute_callable
    return execute_callable(context=context, **execute_callable_kwargs)
           ^^^^^^^^^^^^^^^^^^^^^^^^^^^^^^^^^^^^^^^^^^^^^^^^^^^^^^^^^^^^
  File "/home/airflow/.local/lib/python3.12/site-packages/airflow/models/baseoperator.py", line 400, in wrapper
    return func(self, *args, **kwargs)
           ^^^^^^^^^^^^^^^^^^^^^^^^^^^
  File "/home/airflow/.local/lib/python3.12/site-packages/airflow/operators/python.py", line 235, in execute
    return_value = self.execute_callable()
                   ^^^^^^^^^^^^^^^^^^^^^^^
  File "/home/airflow/.local/lib/python3.12/site-packages/airflow/operators/python.py", line 252, in execute_callable
    return self.python_callable(*self.op_args, **self.op_kwargs)
           ^^^^^^^^^^^^^^^^^^^^^^^^^^^^^^^^^^^^^^^^^^^^^^^^^^^^^
  File "/opt/airflow/dags/fetch_and_store_data.py", line 68, in store_data
    conn = psycopg2.connect(
           ^^^^^^^^^^^^^^^^^
  File "/home/airflow/.local/lib/python3.12/site-packages/psycopg2/__init__.py", line 122, in connect
    conn = _connect(dsn, connection_factory=connection_factory, **kwasync)
           ^^^^^^^^^^^^^^^^^^^^^^^^^^^^^^^^^^^^^^^^^^^^^^^^^^^^^^^^^^^^^^^
psycopg2.OperationalError: connection to server at "postgres" (172.18.0.3), port 5432 failed: FATAL:  password authentication failed for user "fraud"

[2024-05-17T05:33:05.126+0000] {taskinstance.py:1206} INFO - Marking task as UP_FOR_RETRY. dag_id=fetch_and_store_data, task_id=store_data, run_id=scheduled__2024-05-17T05:30:00+00:00, execution_date=20240517T053000, start_date=20240517T053304, end_date=20240517T053305
[2024-05-17T05:33:05.138+0000] {standard_task_runner.py:110} ERROR - Failed to execute job 74 for task store_data (connection to server at "postgres" (172.18.0.3), port 5432 failed: FATAL:  password authentication failed for user "fraud"
; 259)
[2024-05-17T05:33:05.196+0000] {local_task_job_runner.py:240} INFO - Task exited with return code 1
[2024-05-17T05:33:05.216+0000] {taskinstance.py:3498} INFO - 0 downstream tasks scheduled from follow-on schedule check
[2024-05-17T05:33:05.217+0000] {local_task_job_runner.py:222} INFO - ::endgroup::
